<?xml version="1.0"?>
<sdf version="1.6">
  <world name="default">

		<!-- A ground plane -->
		<include>
			<uri>model://ground_plane</uri>
		</include>

		<!-- A global light source -->
		<include>
			<uri>model://sun</uri>
		</include>

		<!-- robot1 -->
	<model name='my_robot1'>
      	<pose>10 0 0.325 0 -0 0</pose>

      	<link name='chassis'>
        	<pose>-0.151427 -0 0.175 0 -0 0</pose>
        	<inertial>
    	        <mass>1.14395</mass>
    	        <inertia>
    	        	<ixx>0.126164</ixx>
    	    	    <ixy>0</ixy>
    	    	    <ixz>0</ixz>
    	    	    <iyy>0.416519</iyy>
    	    	    <iyz>0</iyz>
    	    	    <izz>0.481014</izz>
            	</inertia>
     	   </inertial>
          <visual name='visual'>
          <geometry>
            <box>
              <size>2.01142 1 0.568726</size>
            </box>
          </geometry>
        </visual>
        <collision name='collision'>
          <geometry>
            <box>
              <size>2.01142 1 0.568726</size>
            </box>
          </geometry>
        </collision>
      </link>

      <link name='left_wheel'>
        <pose>0.554283 0.625029 -0.025 -1.5707 0 0</pose>
        <inertial>
          <mass>2</mass>
          <inertia>
            <ixx>0.145833</ixx>
            <ixy>0</ixy>
            <ixz>0</ixz>
            <iyy>0.145833</iyy>
            <iyz>0</iyz>
            <izz>0.125</izz>
          </inertia>
        </inertial>
        <visual name='visual'>
          <geometry>
            <sphere>
              <radius>0.3</radius>
            </sphere>
          </geometry>
        </visual>
        <collision name='collision'>
          <geometry>
            <sphere>
              <radius>0.3</radius>
            </sphere>
          </geometry>
          <surface>
            <friction>
              <ode>
                <mu>1</mu>
                <mu2>1</mu2>
                <slip1>0</slip1>
                <slip2>0</slip2>
              </ode>
            </friction>
            <contact>
              <ode>
                <soft_cfm>0</soft_cfm>
                <soft_erp>0.2</soft_erp>
                <kp>1e+13</kp>
                <kd>1</kd>
                <max_vel>0.01</max_vel>
                <min_depth>0.01</min_depth>
              </ode>
            </contact>
          </surface>
        </collision>
      </link>

      <link name='right_wheel'>
        <pose>0.554282 -0.625029 -0.025 -1.5707 0 0</pose>
        <inertial>
          <mass>2</mass>
          <inertia>
            <ixx>0.145833</ixx>
            <ixy>0</ixy>
            <ixz>0</ixz>
            <iyy>0.145833</iyy>
            <iyz>0</iyz>
            <izz>0.125</izz>
          </inertia>
        </inertial>
        <visual name='visual'>
          <geometry>
            <sphere>
              <radius>0.3</radius>
            </sphere>
          </geometry>
        </visual>
        <collision name='collision'>
          <geometry>
            <sphere>
              <radius>0.3</radius>
            </sphere>
          </geometry>
          <surface>
            <friction>
              <ode>
                <mu>1</mu>
                <mu2>1</mu2>
                <slip1>0</slip1>
                <slip2>0</slip2>
              </ode>
            </friction>
            <contact>
              <ode>
                <soft_cfm>0</soft_cfm>
                <soft_erp>0.2</soft_erp>
                <kp>1e+13</kp>
                <kd>1</kd>
                <max_vel>0.01</max_vel>
                <min_depth>0.01</min_depth>
              </ode>
            </contact>
          </surface>
        </collision>
      </link>

      <link name='caster'>
        <pose>-0.957138 -0 -0.125 0 -0 0</pose>
        <inertial>
          <mass>1</mass>
          <inertia>
            <ixx>0.1</ixx>
            <ixy>0</ixy>
            <ixz>0</ixz>
            <iyy>0.1</iyy>
            <iyz>0</iyz>
            <izz>0.1</izz>
          </inertia>
        </inertial>
        <visual name='visual'>
          <geometry>
            <sphere>
              <radius>0.2</radius>
            </sphere>
          </geometry>
        </visual>
        <collision name='collision'>
          <geometry>
            <sphere>
              <radius>0.2</radius>
            </sphere>
          </geometry>
        </collision>
      </link>

      <joint name='left_wheel_joint' type='revolute'>
        <parent>chassis</parent>
        <child>left_wheel</child>
        <axis>
          <xyz>0 0 1</xyz>
          <limit>
            <lower>-1.79769e+308</lower>
            <upper>1.79769e+308</upper>
          </limit>
        </axis>
      </joint>

      <joint name='right_wheel_joint' type='revolute'>
        <parent>chassis</parent>
        <child>right_wheel</child>
        <axis>
          <xyz>0 0 1</xyz>
          <limit>
            <lower>-1.79769e+308</lower>
            <upper>1.79769e+308</upper>
          </limit>
        </axis>
      </joint>

      <joint name='caster_wheel' type='ball'>
        <parent>chassis</parent>
        <child>caster</child>
      </joint>
      
      <link name="ray_link">
      <pose>0.2 0 0.55 0 0 0</pose>
        <visual name="visual_box">
          <geometry>
            <box>
              <size>0.05 0.05 0.05</size>
            </box>
          </geometry>
        </visual>
        <collision name="collision_box">
          <geometry>
            <box>
              <size>0.05 0.05 0.05</size>
            </box>
          </geometry>
          <laser_retro>100.0</laser_retro>
        </collision>
        
        <sensor name="sensor_ray" type="ray">
   	  		    <ray>
   	  		        <scan>
   	  		            <horizontal>
   	  		                <samples>720</samples>
            		                <resolution>1</resolution>
            			        <min_angle>-1.570796</min_angle>
            			        <max_angle>1.570796</max_angle>
            			    </horizontal>
            			</scan>
            			<vertical>
                		    <samples>100</samples>
                		    <resolution>1.0</resolution>
                		    <min_angle>-0.5236</min_angle>
                		    <max_angle>0.5236</max_angle>
              			</vertical>
            			<range>
            			    <min>0.10</min>
            			    <max>30.0</max>
            			    <resolution>0.01</resolution>
            			</range>
            		    </ray>
            		    <update_rate>30</update_rate>
            		    
            		    <plugin name="gazebo_ros_head_hokuyo_controller" filename="libgazebo_ros_ray_sensor.so">
            		        <ros>
            		            <namespace>/demo1</namespace>
            		            <argument>~/out:=scan</argument>
            		        </ros>
            		        <output_type>sensor_msgs/LaserScan</output_type>
            		    </plugin>
            		    
        		</sensor>
   	
   	</link>

      <joint name="ray_joint" type="fixed">
	<child>ray_link</child>
	<parent>chassis</parent>
      </joint>
      
      <plugin name='diff_drive' filename='libgazebo_ros_diff_drive.so'>
    <ros>
      <namespace>/demo1</namespace>
      <remapping>cmd_vel:=cmd_demo</remapping>
      <remapping>odom:=odom_demo</remapping>
    </ros>

   	    		<!-- wheels -->
   	    		<left_joint>left_wheel_joint</left_joint>
   	    		<right_joint>right_wheel_joint</right_joint>

   	    		<!-- kinematics -->
   	    		<wheel_separation>1.25</wheel_separation>
   	    		<wheel_diameter>0.6</wheel_diameter>

   	    		<!-- limits -->
   	    		<max_wheel_torque>20</max_wheel_torque>
   	    		<max_wheel_acceleration>1.0</max_wheel_acceleration>

   	    		<!-- output -->
   	    		<publish_odom>true</publish_odom>
   	    		<publish_odom_tf>true</publish_odom_tf>
   	    		<publish_wheel_tf>true</publish_wheel_tf>

   	    		<odometry_frame>odom_demo</odometry_frame>
   	    		<robot_base_frame>chassis</robot_base_frame>
   	  		</plugin>

    </model>
    
   		<!-- robot2 -->
		<model name='my_robot2'>
      	<pose>-5 10 0.325 0 -0 0</pose>

      	<link name='chassis'>
        	<pose>-0.151427 -0 0.175 0 -0 0</pose>
        	<inertial>
    	        <mass>1.14395</mass>
    	        <inertia>
    	        	<ixx>0.126164</ixx>
    	    	    <ixy>0</ixy>
    	    	    <ixz>0</ixz>
    	    	    <iyy>0.416519</iyy>
    	    	    <iyz>0</iyz>
    	    	    <izz>0.481014</izz>
            	</inertia>
     	   </inertial>
          <visual name='visual'>
          <geometry>
            <box>
              <size>2.01142 1 0.568726</size>
            </box>
          </geometry>
        </visual>
        <collision name='collision'>
          <geometry>
            <box>
              <size>2.01142 1 0.568726</size>
            </box>
          </geometry>
        </collision>
      </link>

      <link name='left_wheel'>
        <pose>0.554283 0.625029 -0.025 -1.5707 0 0</pose>
        <inertial>
          <mass>2</mass>
          <inertia>
            <ixx>0.145833</ixx>
            <ixy>0</ixy>
            <ixz>0</ixz>
            <iyy>0.145833</iyy>
            <iyz>0</iyz>
            <izz>0.125</izz>
          </inertia>
        </inertial>
        <visual name='visual'>
          <geometry>
            <sphere>
              <radius>0.3</radius>
            </sphere>
          </geometry>
        </visual>
        <collision name='collision'>
          <geometry>
            <sphere>
              <radius>0.3</radius>
            </sphere>
          </geometry>
          <surface>
            <friction>
              <ode>
                <mu>1</mu>
                <mu2>1</mu2>
                <slip1>0</slip1>
                <slip2>0</slip2>
              </ode>
            </friction>
            <contact>
              <ode>
                <soft_cfm>0</soft_cfm>
                <soft_erp>0.2</soft_erp>
                <kp>1e+13</kp>
                <kd>1</kd>
                <max_vel>0.01</max_vel>
                <min_depth>0.01</min_depth>
              </ode>
            </contact>
          </surface>
        </collision>
      </link>

      <link name='right_wheel'>
        <pose>0.554282 -0.625029 -0.025 -1.5707 0 0</pose>
        <inertial>
          <mass>2</mass>
          <inertia>
            <ixx>0.145833</ixx>
            <ixy>0</ixy>
            <ixz>0</ixz>
            <iyy>0.145833</iyy>
            <iyz>0</iyz>
            <izz>0.125</izz>
          </inertia>
        </inertial>
        <visual name='visual'>
          <geometry>
            <sphere>
              <radius>0.3</radius>
            </sphere>
          </geometry>
        </visual>
        <collision name='collision'>
          <geometry>
            <sphere>
              <radius>0.3</radius>
            </sphere>
          </geometry>
          <surface>
            <friction>
              <ode>
                <mu>1</mu>
                <mu2>1</mu2>
                <slip1>0</slip1>
                <slip2>0</slip2>
              </ode>
            </friction>
            <contact>
              <ode>
                <soft_cfm>0</soft_cfm>
                <soft_erp>0.2</soft_erp>
                <kp>1e+13</kp>
                <kd>1</kd>
                <max_vel>0.01</max_vel>
                <min_depth>0.01</min_depth>
              </ode>
            </contact>
          </surface>
        </collision>
      </link>

      <link name='caster'>
        <pose>-0.957138 -0 -0.125 0 -0 0</pose>
        <inertial>
          <mass>1</mass>
          <inertia>
            <ixx>0.1</ixx>
            <ixy>0</ixy>
            <ixz>0</ixz>
            <iyy>0.1</iyy>
            <iyz>0</iyz>
            <izz>0.1</izz>
          </inertia>
        </inertial>
        <visual name='visual'>
          <geometry>
            <sphere>
              <radius>0.2</radius>
            </sphere>
          </geometry>
        </visual>
        <collision name='collision'>
          <geometry>
            <sphere>
              <radius>0.2</radius>
            </sphere>
          </geometry>
        </collision>
      </link>

      <joint name='left_wheel_joint' type='revolute'>
        <parent>chassis</parent>
        <child>left_wheel</child>
        <axis>
          <xyz>0 0 1</xyz>
          <limit>
            <lower>-1.79769e+308</lower>
            <upper>1.79769e+308</upper>
          </limit>
        </axis>
      </joint>

      <joint name='right_wheel_joint' type='revolute'>
        <parent>chassis</parent>
        <child>right_wheel</child>
        <axis>
          <xyz>0 0 1</xyz>
          <limit>
            <lower>-1.79769e+308</lower>
            <upper>1.79769e+308</upper>
          </limit>
        </axis>
      </joint>

      <joint name='caster_wheel' type='ball'>
        <parent>chassis</parent>
        <child>caster</child>
      </joint>
      
      <link name="ray_link">
      <pose>0.2 0 0.55 0 0 0</pose>
        <visual name="visual_box">
          <geometry>
            <box>
              <size>0.05 0.05 0.05</size>
            </box>
          </geometry>
        </visual>
        <collision name="collision_box">
          <geometry>
            <box>
              <size>0.05 0.05 0.05</size>
            </box>
          </geometry>
          <laser_retro>100.0</laser_retro>
        </collision>
        
        <sensor name="sensor_ray" type="ray">
   	  		    <ray>
   	  		        <scan>
   	  		            <horizontal>
   	  		                <samples>720</samples>
            		                <resolution>1</resolution>
            			        <min_angle>-1.570796</min_angle>
            			        <max_angle>1.570796</max_angle>
            			    </horizontal>
            			</scan>
            			<vertical>
                		    <samples>100</samples>
                		    <resolution>1.0</resolution>
                		    <min_angle>-0.5236</min_angle>
                		    <max_angle>0.5236</max_angle>
              			</vertical>
            			<range>
            			    <min>0.10</min>
            			    <max>30.0</max>
            			    <resolution>0.01</resolution>
            			</range>
            		    </ray>
            		    <update_rate>30</update_rate>
            		    
            		    <plugin name="gazebo_ros_head_hokuyo_controller" filename="libgazebo_ros_ray_sensor.so">
            		        <ros>
            		            <namespace>/demo2</namespace>
            		            <argument>~/out:=scan</argument>
            		        </ros>
            		        <output_type>sensor_msgs/LaserScan</output_type>
            		    </plugin>
            		    
        		</sensor>
   	
   	</link>

      <joint name="ray_joint" type="fixed">
	<child>ray_link</child>
	<parent>chassis</parent>
      </joint>
      
      <plugin name='diff_drive' filename='libgazebo_ros_diff_drive.so'>
    <ros>
      <namespace>/demo2</namespace>
      <remapping>cmd_vel:=cmd_demo</remapping>
      <remapping>odom:=odom_demo</remapping>
    </ros>

   	    		<!-- wheels -->
   	    		<left_joint>left_wheel_joint</left_joint>
   	    		<right_joint>right_wheel_joint</right_joint>

   	    		<!-- kinematics -->
   	    		<wheel_separation>1.25</wheel_separation>
   	    		<wheel_diameter>0.6</wheel_diameter>

   	    		<!-- limits -->
   	    		<max_wheel_torque>20</max_wheel_torque>
   	    		<max_wheel_acceleration>1.0</max_wheel_acceleration>

   	    		<!-- output -->
   	    		<publish_odom>true</publish_odom>
   	    		<publish_odom_tf>true</publish_odom_tf>
   	    		<publish_wheel_tf>true</publish_wheel_tf>

   	    		<odometry_frame>odom_demo</odometry_frame>
   	    		<robot_base_frame>chassis</robot_base_frame>
   	  		</plugin>

    </model>
   		
    	<!-- robot3 -->
		<model name='my_robot3'>
      	<pose>-5 -10 0.325 0 -0 0</pose>

      	<link name='chassis'>
        	<pose>-0.151427 -0 0.175 0 -0 0</pose>
        	<inertial>
    	        <mass>1.14395</mass>
    	        <inertia>
    	        	<ixx>0.126164</ixx>
    	    	    <ixy>0</ixy>
    	    	    <ixz>0</ixz>
    	    	    <iyy>0.416519</iyy>
    	    	    <iyz>0</iyz>
    	    	    <izz>0.481014</izz>
            	</inertia>
     	   </inertial>
          <visual name='visual'>
          <geometry>
            <box>
              <size>2.01142 1 0.568726</size>
            </box>
          </geometry>
        </visual>
        <collision name='collision'>
          <geometry>
            <box>
              <size>2.01142 1 0.568726</size>
            </box>
          </geometry>
        </collision>
      </link>

      <link name='left_wheel'>
        <pose>0.554283 0.625029 -0.025 -1.5707 0 0</pose>
        <inertial>
          <mass>2</mass>
          <inertia>
            <ixx>0.145833</ixx>
            <ixy>0</ixy>
            <ixz>0</ixz>
            <iyy>0.145833</iyy>
            <iyz>0</iyz>
            <izz>0.125</izz>
          </inertia>
        </inertial>
        <visual name='visual'>
          <geometry>
            <sphere>
              <radius>0.3</radius>
            </sphere>
          </geometry>
        </visual>
        <collision name='collision'>
          <geometry>
            <sphere>
              <radius>0.3</radius>
            </sphere>
          </geometry>
          <surface>
            <friction>
              <ode>
                <mu>1</mu>
                <mu2>1</mu2>
                <slip1>0</slip1>
                <slip2>0</slip2>
              </ode>
            </friction>
            <contact>
              <ode>
                <soft_cfm>0</soft_cfm>
                <soft_erp>0.2</soft_erp>
                <kp>1e+13</kp>
                <kd>1</kd>
                <max_vel>0.01</max_vel>
                <min_depth>0.01</min_depth>
              </ode>
            </contact>
          </surface>
        </collision>
      </link>

      <link name='right_wheel'>
        <pose>0.554282 -0.625029 -0.025 -1.5707 0 0</pose>
        <inertial>
          <mass>2</mass>
          <inertia>
            <ixx>0.145833</ixx>
            <ixy>0</ixy>
            <ixz>0</ixz>
            <iyy>0.145833</iyy>
            <iyz>0</iyz>
            <izz>0.125</izz>
          </inertia>
        </inertial>
        <visual name='visual'>
          <geometry>
            <sphere>
              <radius>0.3</radius>
            </sphere>
          </geometry>
        </visual>
        <collision name='collision'>
          <geometry>
            <sphere>
              <radius>0.3</radius>
            </sphere>
          </geometry>
          <surface>
            <friction>
              <ode>
                <mu>1</mu>
                <mu2>1</mu2>
                <slip1>0</slip1>
                <slip2>0</slip2>
              </ode>
            </friction>
            <contact>
              <ode>
                <soft_cfm>0</soft_cfm>
                <soft_erp>0.2</soft_erp>
                <kp>1e+13</kp>
                <kd>1</kd>
                <max_vel>0.01</max_vel>
                <min_depth>0.01</min_depth>
              </ode>
            </contact>
          </surface>
        </collision>
      </link>

      <link name='caster'>
        <pose>-0.957138 -0 -0.125 0 -0 0</pose>
        <inertial>
          <mass>1</mass>
          <inertia>
            <ixx>0.1</ixx>
            <ixy>0</ixy>
            <ixz>0</ixz>
            <iyy>0.1</iyy>
            <iyz>0</iyz>
            <izz>0.1</izz>
          </inertia>
        </inertial>
        <visual name='visual'>
          <geometry>
            <sphere>
              <radius>0.2</radius>
            </sphere>
          </geometry>
        </visual>
        <collision name='collision'>
          <geometry>
            <sphere>
              <radius>0.2</radius>
            </sphere>
          </geometry>
        </collision>
      </link>

      <joint name='left_wheel_joint' type='revolute'>
        <parent>chassis</parent>
        <child>left_wheel</child>
        <axis>
          <xyz>0 0 1</xyz>
          <limit>
            <lower>-1.79769e+308</lower>
            <upper>1.79769e+308</upper>
          </limit>
        </axis>
      </joint>

      <joint name='right_wheel_joint' type='revolute'>
        <parent>chassis</parent>
        <child>right_wheel</child>
        <axis>
          <xyz>0 0 1</xyz>
          <limit>
            <lower>-1.79769e+308</lower>
            <upper>1.79769e+308</upper>
          </limit>
        </axis>
      </joint>

      <joint name='caster_wheel' type='ball'>
        <parent>chassis</parent>
        <child>caster</child>
      </joint>
      
      <link name="ray_link">
      <pose>0.2 0 0.55 0 0 0</pose>
        <visual name="visual_box">
          <geometry>
            <box>
              <size>0.05 0.05 0.05</size>
            </box>
          </geometry>
        </visual>
        <collision name="collision_box">
          <geometry>
            <box>
              <size>0.05 0.05 0.05</size>
            </box>
          </geometry>
          <laser_retro>100.0</laser_retro>
        </collision>
        
        <sensor name="sensor_ray" type="ray">
   	  		    <ray>
   	  		        <scan>
   	  		            <horizontal>
   	  		                <samples>720</samples>
            		                <resolution>1</resolution>
            			        <min_angle>-1.570796</min_angle>
            			        <max_angle>1.570796</max_angle>
            			    </horizontal>
            			</scan>
            			<vertical>
                		    <samples>100</samples>
                		    <resolution>1.0</resolution>
                		    <min_angle>-0.5236</min_angle>
                		    <max_angle>0.5236</max_angle>
              			</vertical>
            			<range>
            			    <min>0.10</min>
            			    <max>30.0</max>
            			    <resolution>0.01</resolution>
            			</range>
            		    </ray>
            		    <update_rate>30</update_rate>
            		    
            		    <plugin name="gazebo_ros_head_hokuyo_controller" filename="libgazebo_ros_ray_sensor.so">
            		        <ros>
            		            <namespace>/demo3</namespace>
            		            <argument>~/out:=scan</argument>
            		        </ros>
            		        <output_type>sensor_msgs/LaserScan</output_type>
            		    </plugin>
            		    
        		</sensor>
   	
   	</link>

      <joint name="ray_joint" type="fixed">
	<child>ray_link</child>
	<parent>chassis</parent>
      </joint>
      
      <plugin name='diff_drive' filename='libgazebo_ros_diff_drive.so'>
    <ros>
      <namespace>/demo3</namespace>
      <remapping>cmd_vel:=cmd_demo</remapping>
      <remapping>odom:=odom_demo</remapping>
    </ros>

   	    		<!-- wheels -->
   	    		<left_joint>left_wheel_joint</left_joint>
   	    		<right_joint>right_wheel_joint</right_joint>

   	    		<!-- kinematics -->
   	    		<wheel_separation>1.25</wheel_separation>
   	    		<wheel_diameter>0.6</wheel_diameter>

   	    		<!-- limits -->
   	    		<max_wheel_torque>20</max_wheel_torque>
   	    		<max_wheel_acceleration>1.0</max_wheel_acceleration>

   	    		<!-- output -->
   	    		<publish_odom>true</publish_odom>
   	    		<publish_odom_tf>true</publish_odom_tf>
   	    		<publish_wheel_tf>true</publish_wheel_tf>

   	    		<odometry_frame>odom_demo</odometry_frame>
   	    		<robot_base_frame>chassis</robot_base_frame>
   	  		</plugin>

    </model>
		
	</world>
</sdf>
